from datetime import datetime, timedelta
from jose import JWTError, jwt
from passlib.context import CryptContext
from fastapi import Depends, HTTPException, status
from fastapi.security import OAuth2PasswordBearer
from sqlalchemy.orm import Session

from . import models, database

# Configurações JWT
SECRET_KEY = "secret123"  # ⚠️ depois coloca isso em .env
ALGORITHM = "HS256"
ACCESS_TOKEN_EXPIRE_MINUTES = 60

# Password hashing
pwd_context = CryptContext(schemes=["bcrypt"], deprecated="auto")

# OAuth2 schema
oauth2_scheme = OAuth2PasswordBearer(tokenUrl="auth/login")

# Funções utilitárias
def verify_password(plain_password, hashed_password):
    return pwd_context.verify(plain_password, hashed_password)

def get_password_hash(password):
    return pwd_context.hash(password)

def create_access_token(data: dict, expires_delta: timedelta | None = None):
    to_encode = data.copy()
    expire = datetime.utcnow() + (expires_delta or timedelta(minutes=ACCESS_TOKEN_EXPIRE_MINUTES))
    to_encode.update({"exp": expire})
    return jwt.encode(to_encode, SECRET_KEY, algorithm=ALGORITHM)

def get_user_by_email(db: Session, email: str):
    return db.query(models.User).filter(models.User.email == email).first()

def authenticate_user(db: Session, email: str, password: str):
    user = get_user_by_email(db, email)
    if not user or not verify_password(password, user.senha):
        return None
    return user

def get_current_user(db: Session = Depends(database.get_db), token: str = Depends(oauth2_scheme)):
    credentials_exception = HTTPException(
        status_code=status.HTTP_401_UNAUTHORIZED,
        detail="Não foi possível validar as credenciais",
        headers={"WWW-Authenticate": "Bearer"},
    )
    try:
        payload = jwt.decode(token, SECRET_KEY, algorithms=[ALGORITHM])
        email: str = payload.get("sub")
        if email is None:
            raise credentials_exception
    except JWTError:
        raise credentials_exception
    user = get_user_by_email(db, email=email)
    if user is None:
        raise credentials_exception
    return user
